<?xml version="1.0" ?>
<!-- =================================================================================== -->
<!-- |    This document was autogenerated by xacro from utv_chassis.urdf.xacro         | -->
<!-- |    EDITING THIS FILE BY HAND IS NOT RECOMMENDED                                 | -->
<!-- =================================================================================== -->
<robot name="utv_chassis" xmlns:xacro="http://www.ros.org/wiki/xacro">
  <!-- Used for fixing robot to Gazebo 'base_link' -->
  <!-- <link name="world"/> -->
  <!-- base_link must have geometry so that its axes can be displayed in
       rviz. -->
  <link name="base_link">
    <visual>
      <origin rpy="0 0 0" xyz="0 0 0"/>
      <geometry>
        <box size="0.01 0.01 0.01"/>
      </geometry>
      <material name="chassis_mat"/>
    </visual>
  </link>
  <gazebo reference="base_link">
    <material>Gazebo/Grey</material>
  </gazebo>
  <!-- chassis-->
  <link name="chassis">
    <visual>
      <origin rpy="0 0 0" xyz="0 0 0"/>
      <geometry>
        <box size="2.29 0.5 0.1"/>
        <!-- <mesh filename="package://prowler_vehicle_description/meshes/utv_full.dae" /> -->
      </geometry>
      <material name="tire_mat"/>
    </visual>
    <collision>
      <origin rpy="0 0 0" xyz="0 0 0"/>
      <geometry>
        <box size="2.29 0.5 0.1"/>
      </geometry>
    </collision>
    <inertial>
      <mass value="400"/>
      <origin rpy="0 0 0" xyz="0 0 0"/>
      <inertia ixx="175.136666667" ixy="0" ixz="0" iyy="8.66666666667" iyz="0" izz="183.136666667"/>
    </inertial>
  </link>
  <joint name="base_link_to_chassis" type="fixed">
    <parent link="base_link"/>
    <child link="chassis"/>
  </joint>
  <!--   <joint name="world_to_chassis_joint" type="fixed">
    <parent link="world"/>
    <child link="chassis"/>
    <origin xyz="0 0 2" />
  </joint> -->
  <!-- shock_lower_front_left -->
  <link name="shock_lower_front_left">
    <visual>
      <origin xyz="0 0 0"/>
      <geometry>
        <cylinder length="0.258" radius="0.05"/>
      </geometry>
      <material name="tire_mat"/>
    </visual>
    <collision>
      <origin xyz="0 0 0"/>
      <geometry>
        <cylinder length="0.258" radius="0.05"/>
      </geometry>
    </collision>
    <inertial>
      <origin rpy="0 0 0" xyz="0 0 0"/>
      <mass value="1"/>
      <inertia ixx="0.006572" ixy="0" ixz="0" iyy="0.006572" iyz="0" izz="0.00205"/>
    </inertial>
  </link>
  <!-- JOINT shock_lower_front_left TO shock_upper_front_left -->
  <joint name="left_front_shock" type="prismatic">
    <parent link="chassis"/>
    <child link="shock_lower_front_left"/>
    <origin xyz="1.145 0.56 -0.079"/>
    <axis xyz="0 0 1"/>
    <limit effort="20" lower="0" upper="0.208" velocity="10"/>
  </joint>
  <transmission name="front_left_shock_trans">
    <type>transmission_interface/SimpleTransmission</type>
    <joint name="left_front_shock">
      <hardwareInterface>EffortJointInterface</hardwareInterface>
    </joint>
    <actuator name="front_left_shock_act">
      <!-- This hardwareInterface element exists for compatibility
             with ROS Hydro. -->
      <hardwareInterface>EffortJointInterface</hardwareInterface>
      <mechanicalReduction>1</mechanicalReduction>
    </actuator>
  </transmission>
  <!-- shock_lower_front_right -->
  <link name="shock_lower_front_right">
    <visual>
      <origin xyz="0 0 0"/>
      <geometry>
        <cylinder length="0.258" radius="0.05"/>
      </geometry>
      <material name="tire_mat"/>
    </visual>
    <collision>
      <origin xyz="0 0 0"/>
      <geometry>
        <cylinder length="0.258" radius="0.05"/>
      </geometry>
    </collision>
    <inertial>
      <origin rpy="0 0 0" xyz="0 0 0"/>
      <mass value="1"/>
      <inertia ixx="0.006572" ixy="0" ixz="0" iyy="0.006572" iyz="0" izz="0.00205"/>
    </inertial>
  </link>
  <!-- JOINT shock_lower_front_right TO shock_upper_front_right -->
  <joint name="right_front_shock" type="prismatic">
    <parent link="chassis"/>
    <child link="shock_lower_front_right"/>
    <origin xyz="1.145 -1.12 -0.079"/>
    <axis xyz="0 0 1"/>
    <limit effort="20" lower="0" upper="0.208" velocity="10"/>
  </joint>
  <transmission name="front_right_shock_trans">
    <type>transmission_interface/SimpleTransmission</type>
    <joint name="right_front_shock">
      <hardwareInterface>EffortJointInterface</hardwareInterface>
    </joint>
    <actuator name="front_right_shock_act">
      <!-- This hardwareInterface element exists for compatibility
             with ROS Hydro. -->
      <hardwareInterface>EffortJointInterface</hardwareInterface>
      <mechanicalReduction>1</mechanicalReduction>
    </actuator>
  </transmission>
  <!-- steer_link_front_left -->
  <link name="steer_link_front_left">
    <visual>
      <origin rpy="1.57079633 0 0" xyz="0 0.1 0"/>
      <geometry>
        <cylinder length="0.2" radius="0.05"/>
      </geometry>
      <material name="tire_mat"/>
    </visual>
    <collision>
      <origin rpy="1.57079633 0 0" xyz="0 0.1 0"/>
      <geometry>
        <cylinder length="0.2" radius="0.05"/>
      </geometry>
    </collision>
    <inertial>
      <origin rpy="0 0 0" xyz="0 0 0"/>
      <mass value="1"/>
      <inertia ixx="0.00435833333333" ixy="0" ixz="0" iyy="0.00435833333333" iyz="0" izz="0.00205"/>
    </inertial>
  </link>
  <!-- JOINT steer_link_front_left TO shock_lower_front_left -->
  <joint name="left_steering_joint" type="revolute">
    <parent link="shock_lower_front_left"/>
    <child link="steer_link_front_left"/>
    <origin xyz="0 0 -0.079"/>
    <axis xyz="0 0 1"/>
    <limit effort="50" lower="-0.785398163" upper="0.785398163" velocity="4.553"/>
  </joint>
  <transmission name="front_left_steering_trans">
    <type>transmission_interface/SimpleTransmission</type>
    <joint name="left_steering_joint">
      <hardwareInterface>EffortJointInterface</hardwareInterface>
    </joint>
    <actuator name="front_left_steering_act">
      <!-- This hardwareInterface element exists for compatibility
             with ROS Hydro. -->
      <hardwareInterface>EffortJointInterface</hardwareInterface>
      <mechanicalReduction>1</mechanicalReduction>
    </actuator>
  </transmission>
  <!-- steer_link_front_right -->
  <link name="steer_link_front_right">
    <visual>
      <origin rpy="1.57079633 0 0" xyz="0 -0.1 0"/>
      <geometry>
        <cylinder length="0.2" radius="0.05"/>
      </geometry>
      <material name="tire_mat"/>
    </visual>
    <collision>
      <origin rpy="1.57079633 0 0" xyz="0 0 0"/>
      <geometry>
        <cylinder length="0.2" radius="0.05"/>
      </geometry>
    </collision>
    <inertial>
      <origin rpy="0 0 0" xyz="0 0 0"/>
      <mass value="1"/>
      <inertia ixx="0.00435833333333" ixy="0" ixz="0" iyy="0.00435833333333" iyz="0" izz="0.00205"/>
    </inertial>
  </link>
  <!-- JOINT steer_link_front_right TO shock_lower_front_right -->
  <joint name="right_steering_joint" type="revolute">
    <parent link="shock_lower_front_right"/>
    <child link="steer_link_front_right"/>
    <origin xyz="0 0 -0.079"/>
    <axis xyz="0 0 1"/>
    <limit effort="50" lower="-0.785398163" upper="0.785398163" velocity="4.553"/>
  </joint>
  <transmission name="front_right_steering_trans">
    <type>transmission_interface/SimpleTransmission</type>
    <joint name="right_steering_joint">
      <hardwareInterface>EffortJointInterface</hardwareInterface>
    </joint>
    <actuator name="front_right_steering_act">
      <!-- This hardwareInterface element exists for compatibility
             with ROS Hydro. -->
      <hardwareInterface>EffortJointInterface</hardwareInterface>
      <mechanicalReduction>1</mechanicalReduction>
    </actuator>
  </transmission>
  <!-- wheel_front_left -->
  <link name="left_front_wheel">
    <visual>
      <origin rpy="1.57079633 0 0" xyz="0 0.1 0"/>
      <geometry>
        <cylinder length="0.2" radius="0.32"/>
      </geometry>
      <material name="tire_mat"/>
    </visual>
    <collision>
      <origin rpy="1.57079633 0 0" xyz="0 0.1 0"/>
      <geometry>
        <cylinder length="0.2" radius="0.32"/>
      </geometry>
    </collision>
    <inertial>
      <origin rpy="1.57079633 0 0" xyz="0 0 0"/>
      <mass value="3"/>
      <inertia ixx="0.158875" ixy="0" ixz="0" iyy="0.158875" iyz="0" izz="0.29775"/>
    </inertial>
  </link>
  <!-- JOINT wheel_front_left TO steer_link_front_left -->
  <joint name="left_front_axle" type="continuous">
    <parent link="steer_link_front_left"/>
    <child link="left_front_wheel"/>
    <origin xyz="0 0.2 0 "/>
    <axis xyz="0 1 0"/>
    <limit effort="100" velocity="244.8696"/>
  </joint>
  <transmission name="left_front_axle_trans">
    <type>transmission_interface/SimpleTransmission</type>
    <joint name="left_front_axle">
      <hardwareInterface>EffortJointInterface</hardwareInterface>
    </joint>
    <actuator name="left_front_axle_act">
      <!-- This hardwareInterface element exists for compatibility
             with ROS Hydro. -->
      <hardwareInterface>EffortJointInterface</hardwareInterface>
      <mechanicalReduction>1</mechanicalReduction>
    </actuator>
  </transmission>
  <!-- wheel_front_right -->
  <link name="right_front_wheel">
    <visual>
      <origin rpy="1.57079633 0 0" xyz="0 -0.1 0"/>
      <geometry>
        <cylinder length="0.2" radius="0.32"/>
      </geometry>
      <material name="tire_mat"/>
    </visual>
    <collision>
      <origin rpy="1.57079633 0 0" xyz="0 -0.1 0"/>
      <geometry>
        <cylinder length="0.2" radius="0.32"/>
      </geometry>
    </collision>
    <inertial>
      <origin rpy="1.57079633 0 0" xyz="0 0 0"/>
      <mass value="3"/>
      <inertia ixx="0.158875" ixy="0" ixz="0" iyy="0.158875" iyz="0" izz="0.29775"/>
    </inertial>
  </link>
  <!-- JOINT wheel_front_right TO steer_link_front_right -->
  <joint name="right_front_axle" type="continuous">
    <parent link="steer_link_front_right"/>
    <child link="right_front_wheel"/>
    <origin xyz="0 -0.2 0 "/>
    <axis xyz="0 1 0"/>
    <limit effort="100" velocity="244.8696"/>
  </joint>
  <transmission name="right_front_axle_trans">
    <type>transmission_interface/SimpleTransmission</type>
    <joint name="right_front_axle">
      <hardwareInterface>EffortJointInterface</hardwareInterface>
    </joint>
    <actuator name="right_front_axle_act">
      <!-- This hardwareInterface element exists for compatibility
             with ROS Hydro. -->
      <hardwareInterface>EffortJointInterface</hardwareInterface>
      <mechanicalReduction>1</mechanicalReduction>
    </actuator>
  </transmission>
  <!-- shock_lower_rear_left -->
  <link name="shock_lower_rear_left">
    <visual>
      <origin xyz="0 0 0"/>
      <geometry>
        <cylinder length="0.258" radius="0.05"/>
      </geometry>
      <material name="tire_mat"/>
    </visual>
    <collision>
      <origin xyz="0 0 0"/>
      <geometry>
        <cylinder length="0.258" radius="0.05"/>
      </geometry>
    </collision>
    <inertial>
      <origin rpy="0 0 0" xyz="0 0 0"/>
      <mass value="1"/>
      <inertia ixx="0.006572" ixy="0" ixz="0" iyy="0.006572" iyz="0" izz="0.00205"/>
    </inertial>
  </link>
  <!-- JOINT shock_lower_rear_left TO shock_upper_rear_left -->
  <joint name="left_rear_shock" type="prismatic">
    <parent link="chassis"/>
    <child link="shock_lower_rear_left"/>
    <origin xyz="-1.145 1.12 -0.079"/>
    <axis xyz="0 0 1"/>
    <limit effort="20" lower="0" upper="0.208" velocity="10"/>
  </joint>
  <transmission name="rear_left_shock_trans">
    <type>transmission_interface/SimpleTransmission</type>
    <joint name="left_rear_shock">
      <hardwareInterface>EffortJointInterface</hardwareInterface>
    </joint>
    <actuator name="rear_left_shock_act">
      <!-- This hardwareInterface element exists for compatibility
             with ROS Hydro. -->
      <hardwareInterface>EffortJointInterface</hardwareInterface>
      <mechanicalReduction>1</mechanicalReduction>
    </actuator>
  </transmission>
  <!-- shock_lower_rear_right -->
  <link name="shock_lower_rear_right">
    <visual>
      <origin xyz="0 0 0"/>
      <geometry>
        <cylinder length="0.258" radius="0.05"/>
      </geometry>
      <material name="tire_mat"/>
    </visual>
    <collision>
      <origin xyz="0 0 0"/>
      <geometry>
        <cylinder length="0.258" radius="0.05"/>
      </geometry>
    </collision>
    <inertial>
      <origin rpy="0 0 0" xyz="0 0 0"/>
      <mass value="1"/>
      <inertia ixx="0.006572" ixy="0" ixz="0" iyy="0.006572" iyz="0" izz="0.00205"/>
    </inertial>
  </link>
  <!-- JOINT shock_lower_rear_right TO shock_upper_rear_right -->
  <joint name="right_rear_shock" type="prismatic">
    <parent link="chassis"/>
    <child link="shock_lower_rear_right"/>
    <origin xyz="-1.145 -1.12 -0.079"/>
    <axis xyz="0 0 1"/>
    <limit effort="20" lower="0" upper="0.208" velocity="10"/>
  </joint>
  <transmission name="rear_right_shock_trans">
    <type>transmission_interface/SimpleTransmission</type>
    <joint name="right_rear_shock">
      <hardwareInterface>EffortJointInterface</hardwareInterface>
    </joint>
    <actuator name="rear_right_shock_act">
      <!-- This hardwareInterface element exists for compatibility
             with ROS Hydro. -->
      <hardwareInterface>EffortJointInterface</hardwareInterface>
      <mechanicalReduction>1</mechanicalReduction>
    </actuator>
  </transmission>
  <!-- wheel_rear_left -->
  <link name="left_rear_wheel">
    <visual>
      <origin rpy="1.57079633 0 0" xyz="0 0.1 0"/>
      <geometry>
        <cylinder length="0.2" radius="0.32"/>
      </geometry>
      <material name="tire_mat"/>
    </visual>
    <collision>
      <origin rpy="1.57079633 0 0" xyz="0 0.1 0"/>
      <geometry>
        <cylinder length="0.2" radius="0.32"/>
      </geometry>
    </collision>
    <inertial>
      <origin rpy="1.57079633 0 0" xyz="0 0 0"/>
      <mass value="3"/>
      <inertia ixx="0.158875" ixy="0" ixz="0" iyy="0.158875" iyz="0" izz="0.29775"/>
    </inertial>
  </link>
  <!-- JOINT wheel_rear_left TO steer_link_rear_left -->
  <joint name="left_rear_axle" type="continuous">
    <parent link="shock_lower_rear_left"/>
    <child link="left_rear_wheel"/>
    <origin xyz="0 0.2 0 "/>
    <axis xyz="0 1 0"/>
    <limit effort="100" velocity="244.8696"/>
  </joint>
  <transmission name="left_rear_axle_trans">
    <type>transmission_interface/SimpleTransmission</type>
    <joint name="left_rear_axle">
      <hardwareInterface>EffortJointInterface</hardwareInterface>
    </joint>
    <actuator name="left_rear_axle_act">
      <!-- This hardwareInterface element exists for compatibility
             with ROS Hydro. -->
      <hardwareInterface>EffortJointInterface</hardwareInterface>
      <mechanicalReduction>1</mechanicalReduction>
    </actuator>
  </transmission>
  <!-- wheel_rear_right -->
  <link name="right_rear_wheel">
    <visual>
      <origin rpy="1.57079633 0 0" xyz="0 -0.1 0"/>
      <geometry>
        <cylinder length="0.2" radius="0.32"/>
      </geometry>
      <material name="tire_mat"/>
    </visual>
    <collision>
      <origin rpy="1.57079633 0 0" xyz="0 -0.1 0"/>
      <geometry>
        <cylinder length="0.2" radius="0.32"/>
      </geometry>
    </collision>
    <inertial>
      <origin rpy="1.57079633 0 0" xyz="0 0 0"/>
      <mass value="3"/>
      <inertia ixx="0.158875" ixy="0" ixz="0" iyy="0.158875" iyz="0" izz="0.29775"/>
    </inertial>
  </link>
  <!-- JOINT wheel_rear_right TO steer_link_rear_right -->
  <joint name="right_rear_axle" type="continuous">
    <parent link="shock_lower_rear_right"/>
    <child link="right_rear_wheel"/>
    <origin xyz="0 -0.2 0 "/>
    <axis xyz="0 1 0"/>
    <limit effort="100" velocity="244.8696"/>
  </joint>
  <transmission name="right_rear_axle_trans">
    <type>transmission_interface/SimpleTransmission</type>
    <joint name="right_rear_axle">
      <hardwareInterface>EffortJointInterface</hardwareInterface>
    </joint>
    <actuator name="right_rear_axle_act">
      <!-- This hardwareInterface element exists for compatibility
             with ROS Hydro. -->
      <hardwareInterface>EffortJointInterface</hardwareInterface>
      <mechanicalReduction>1</mechanicalReduction>
    </actuator>
  </transmission>
  <!-- gazebo_ros_control plugin -->
  <gazebo>
    <plugin filename="libgazebo_ros_control.so" name="gazebo_ros_control"/>
  </gazebo>
</robot>

