<?xml version="1.0" ?>
<!-- =================================================================================== -->
<!-- |    This document was autogenerated by xacro from front_axle.urdf.xacro          | -->
<!-- |    EDITING THIS FILE BY HAND IS NOT RECOMMENDED                                 | -->
<!-- =================================================================================== -->
<robot name="front_axle_assembly" xmlns:xacro="http://www.ros.org/wiki/xacro">
  <!-- Used for fixing robot to Gazebo 'base_link' -->
  <link name="world"/>
  <joint name="fixed" type="fixed">
    <parent link="world"/>
    <child link="front_axle"/>
    <origin xyz="0 0 1"/>
  </joint>
  <!-- front_axle-->
  <link name="front_axle">
    <visual>
      <origin rpy="0 0 0" xyz="0 0 0"/>
      <geometry>
        <box size="0.1 1.12 0.1"/>
      </geometry>
      <material name="mat_1"/>
    </visual>
    <collision>
      <origin rpy="0 0 0" xyz="0 0 0"/>
      <geometry>
        <box size="0.1 1.12 0.1"/>
      </geometry>
    </collision>
    <inertial>
      <mass value="10"/>
      <origin/>
      <inertia ixx="1.05366666667" ixy="0" ixz="0" iyy="0.0166666666667" iyz="0" izz="1.05366666667"/>
    </inertial>
  </link>
  <!-- shock_upper_front_left -->
  <link name="shock_upper_front_left">
    <visual>
      <origin xyz="0 0 0"/>
      <geometry>
        <cylinder length="0.1" radius="0.1"/>
      </geometry>
      <material name="tire_mat"/>
    </visual>
    <collision>
      <origin xyz="0 0 0"/>
      <geometry>
        <cylinder length="0.1" radius="0.1"/>
      </geometry>
    </collision>
    <inertial>
      <mass value="3"/>
      <inertia ixx="0.016075" ixy="0" ixz="0" iyy="0.016075" iyz="0" izz="0.02715"/>
    </inertial>
  </link>
  <!-- JOINT shock_upper_front_left TO front_axle -->
  <joint name="shock_front_left_to_front_axle_joint" type="fixed">
    <parent link="front_axle"/>
    <child link="shock_upper_front_left"/>
    <origin xyz="0 0.56 0"/>
  </joint>
  <!-- shock_upper_front_right -->
  <link name="shock_upper_front_right">
    <visual>
      <origin xyz="0 0 0"/>
      <geometry>
        <cylinder length="0.1" radius="0.1"/>
      </geometry>
      <material name="tire_mat"/>
    </visual>
    <collision>
      <origin xyz="0 0 0"/>
      <geometry>
        <cylinder length="0.1" radius="0.1"/>
      </geometry>
    </collision>
    <inertial>
      <mass value="3"/>
      <inertia ixx="0.016075" ixy="0" ixz="0" iyy="0.016075" iyz="0" izz="0.02715"/>
    </inertial>
  </link>
  <!-- JOINT shock_upper_front_right TO front_axle -->
  <joint name="shock_front_right_to_front_axle_joint" type="fixed">
    <parent link="front_axle"/>
    <child link="shock_upper_front_right"/>
    <origin xyz="0 -0.56 0"/>
  </joint>
  <!-- shock_lower_front_left -->
  <link name="shock_lower_front_left">
    <visual>
      <origin xyz="0 0 0"/>
      <geometry>
        <cylinder length="0.258" radius="0.05"/>
      </geometry>
      <material name="tire_mat"/>
    </visual>
    <collision>
      <origin xyz="0 0 0"/>
      <geometry>
        <cylinder length="0.258" radius="0.05"/>
      </geometry>
    </collision>
    <inertial>
      <mass value="1"/>
      <inertia ixx="0.006572" ixy="0" ixz="0" iyy="0.006572" iyz="0" izz="0.00205"/>
    </inertial>
  </link>
  <!-- JOINT shock_lower_front_left TO shock_upper_front_left -->
  <joint name="shock_front_left_upper_to_lower_joint" type="prismatic">
    <parent link="shock_upper_front_left"/>
    <child link="shock_lower_front_left"/>
    <origin xyz="0 0 -0.079"/>
    <axis xyz="0 0 1"/>
    <limit effort="20" lower="0" upper="0.208" velocity="1000"/>
  </joint>
  <!-- shock_lower_front_right -->
  <link name="shock_lower_front_right">
    <visual>
      <origin xyz="0 0 0"/>
      <geometry>
        <cylinder length="0.258" radius="0.05"/>
      </geometry>
      <material name="tire_mat"/>
    </visual>
    <collision>
      <origin xyz="0 0 0"/>
      <geometry>
        <cylinder length="0.258" radius="0.05"/>
      </geometry>
    </collision>
    <inertial>
      <mass value="1"/>
      <inertia ixx="0.006572" ixy="0" ixz="0" iyy="0.006572" iyz="0" izz="0.00205"/>
    </inertial>
  </link>
  <!-- JOINT shock_lower_front_right TO shock_upper_front_right -->
  <joint name="shock_front_right_upper_to_lower_joint" type="prismatic">
    <parent link="shock_upper_front_right"/>
    <child link="shock_lower_front_right"/>
    <origin xyz="0 0 -0.079"/>
    <axis xyz="0 0 1"/>
    <limit effort="20" lower="0" upper="0.208" velocity="1000"/>
  </joint>
  <!-- steer_link_front_left -->
  <link name="steer_link_front_left">
    <visual>
      <origin rpy="1.57079633 0 0" xyz="0 0 0"/>
      <geometry>
        <cylinder length="0.1" radius="0.05"/>
      </geometry>
      <material name="tire_mat"/>
    </visual>
    <collision>
      <origin rpy="1.57079633 0 0" xyz="0 0 0"/>
      <geometry>
        <cylinder length="0.1" radius="0.05"/>
      </geometry>
    </collision>
    <inertial>
      <mass value="1"/>
      <inertia ixx="0.00185833333333" ixy="0" ixz="0" iyy="0.00185833333333" iyz="0" izz="0.00205"/>
    </inertial>
  </link>
  <!-- JOINT steer_link_front_left TO shock_lower_front_left -->
  <joint name="steer_link_front_left_to_shock_lower_joint" type="revolute">
    <parent link="shock_lower_front_left"/>
    <child link="steer_link_front_left"/>
    <origin xyz="0 0.05 -0.129"/>
  </joint>
</robot>

