<?xml version="1.0" ?>
<!-- =================================================================================== -->
<!-- |    This document was autogenerated by xacro from steering_linkage.urdf.xacro    | -->
<!-- |    EDITING THIS FILE BY HAND IS NOT RECOMMENDED                                 | -->
<!-- =================================================================================== -->
<robot name="steering_linkage" xmlns:xacro="http://www.ros.org/wiki/xacro">
  <!--Materials -->
  <material name="mat_1">
    <color rgba="0 0 1 1"/>
  </material>
  <material name="mat_2">
    <color rgba="0.5 0.5 0.5 1"/>
  </material>
  <material name="mat_3">
    <color rgba="0 0 0 1"/>
  </material>
  <!-- Macros -->
  <!-- Used for fixing robot to Gazebo 'base_link' -->
  <link name="world"/>
  <joint name="fixed" type="fixed">
    <parent link="world"/>
    <child link="steer_beam"/>
  </joint>
  <!-- steer_beam-->
  <link name="steer_beam">
    <visual>
      <origin rpy="0 0 0" xyz="0 0 0.05"/>
      <geometry>
        <box size="0.1 1.12 0.1"/>
      </geometry>
      <material name="mat_1"/>
    </visual>
    <collision>
      <origin rpy="0 0 0" xyz="0 0 0.05 "/>
      <geometry>
        <box size="0.1 1.12 0.1"/>
      </geometry>
    </collision>
    <inertial>
      <mass value="10"/>
      <origin/>
      <inertia ixx="1.05366666667" ixy="0" ixz="0" iyy="0.0166666666667" iyz="0" izz="1.05366666667"/>
    </inertial>
  </link>
  <gazebo reference="steer_beam">
    <material>Gazebo/Blue</material>
  </gazebo>
  <!-- control_arm left -->
  <link name="control_arm_left">
    <visual>
      <origin rpy="0 0 0" xyz="0 -0.125 0 "/>
      <geometry>
        <box size="0.3 0.1 0.1"/>
      </geometry>
      <material name="mat_3"/>
    </visual>
    <collision>
      <origin rpy="0 0 0" xyz="0 -0.125 0 "/>
      <geometry>
        <box size="0.3 0.1 0.1"/>
      </geometry>
    </collision>
    <inertial>
      <mass value="2"/>
      <origin/>
      <inertia ixx="0.00333333333333" ixy="0" ixz="0" iyy="0.0166666666667" iyz="0" izz="0.0166666666667"/>
    </inertial>
  </link>
  <!-- control_arm right -->
  <link name="control_arm_right">
    <visual>
      <origin rpy="0 0 0" xyz="0 -0.125 0 "/>
      <geometry>
        <box size="0.3 0.1 0.1"/>
      </geometry>
      <material name="mat_3"/>
    </visual>
    <collision>
      <origin rpy="0 0 0" xyz="0 -0.125 0 "/>
      <geometry>
        <box size="0.3 0.1 0.1"/>
      </geometry>
    </collision>
    <inertial>
      <mass value="2"/>
      <origin/>
      <inertia ixx="0.00333333333333" ixy="0" ixz="0" iyy="0.0166666666667" iyz="0" izz="0.0166666666667"/>
    </inertial>
  </link>
  <!-- steer_beam to control_arm_left joint -->
  <joint name="steer_beam_to_left_control_arm_joint" type="revolute">
    <parent link="steer_beam"/>
    <child link="control_arm_left"/>
    <origin rpy="0 0 0" xyz="0 0.535 0"/>
    <axis xyz="0 0 -1"/>
    <limit effort="50" lower="-0.785398163" upper="0.785398163" velocity="10"/>
  </joint>
  <!-- steer_beam to control_arm_right joint -->
  <joint name="steer_beam_to_right_control_arm_joint" type="revolute">
    <parent link="steer_beam"/>
    <child link="control_arm_right"/>
    <origin rpy="0 0 0" xyz="0 -0.535 0"/>
    <axis xyz="0 0 -1"/>
    <limit effort="50" lower="-0.785398163" upper="0.785398163" velocity="10"/>
  </joint>
</robot>

