<?xml version="1.0" ?>
<!-- =================================================================================== -->
<!-- |    This document was autogenerated by xacro from shock.urdf.xacro               | -->
<!-- |    EDITING THIS FILE BY HAND IS NOT RECOMMENDED                                 | -->
<!-- =================================================================================== -->
<robot name="shock" xmlns:xacro="http://www.ros.org/wiki/xacro">
  <material name="chassis_mat">
    <color rgba="0.5 0.5 0.5 1"/>
  </material>
  <material name="tire_mat">
    <color rgba="0 0 0 1"/>
  </material>
  <!-- Base Block -->
  <link name="base_block">
    <visual>
      <origin xyz="0 0 0.5"/>
      <geometry>
        <box size="1 1 1"/>
      </geometry>
      <material name="chassis_mat"/>
    </visual>
    <collision>
      <origin xyz="0 0 0.5"/>
      <geometry>
        <box size="1 1 1"/>
      </geometry>
    </collision>
    <inertial>
      <origin/>
      <mass value="100"/>
      <inertia ixx="16.6666666667" ixy="0" ixz="0" iyy="16.6666666667" iyz="0" izz="16.6666666667"/>
    </inertial>
  </link>
  <gazebo reference="base_block">
    <material>Gazebo/Grey</material>
  </gazebo>
  <!-- Cylinder -->
  <link name="shock_lower">
    <visual>
      <origin xyz="0 0 0"/>
      <geometry>
        <cylinder length="0.3" radius="0.05"/>
      </geometry>
      <material name="chassis_mat"/>
    </visual>
    <collision>
      <origin xyz="0 0 0"/>
      <geometry>
        <cylinder length="0.3" radius="0.05"/>
      </geometry>
    </collision>
    <inertial>
      <mass value="1"/>
      <inertia ixx="0.008525" ixy="0" ixz="0" iyy="0.008525" iyz="0" izz="0.00205"/>
    </inertial>
  </link>
  <gazebo reference="shock_lower">
    <material>Gazebo/Grey</material>
  </gazebo>
  <link name="shock_upper">
    <visual>
      <origin xyz="0 0 0"/>
      <geometry>
        <cylinder length="0.3" radius="0.05"/>
      </geometry>
      <material name="chassis_mat"/>
    </visual>
    <collision>
      <origin xyz="0 0 0"/>
      <geometry>
        <cylinder length="0.3" radius="0.05"/>
      </geometry>
    </collision>
    <inertial>
      <mass value="1"/>
      <inertia ixx="0.008525" ixy="0" ixz="0" iyy="0.008525" iyz="0" izz="0.00205"/>
    </inertial>
  </link>
  <gazebo reference="shock_upper">
    <material>Gazebo/Grey</material>
  </gazebo>
  <joint name="shock_absorber" type="prismatic">
    <parent link="shock_lower"/>
    <child link="shock_upper"/>
    <origin xyz="0 0 0.3"/>
    <axis xyz="0 0 -1"/>
    <limit effort="20" lower="-0.15" upper="0.15" velocity="1000"/>
  </joint>
  <joint name="shock_base_block" type="fixed">
    <parent link="base_block"/>
    <child link="shock_lower"/>
    <origin rpy="0 0 0" xyz="0 0 1.15"/>
  </joint>
  <transmission name="shock_absorber_trans">
    <type>transmission_interface/SimpleTransmission</type>
    <joint name="shock_absorber">
      <hardwareInterface>EffortJointInterface</hardwareInterface>
    </joint>
    <actuator name="shock_absorber_act">
      <!-- This hardwareInterface element exists for compatibility
	             with ROS Hydro. -->
      <hardwareInterface>EffortJointInterface</hardwareInterface>
      <mechanicalReduction>1</mechanicalReduction>
    </actuator>
  </transmission>
  <gazebo>
    <plugin filename="libgazebo_ros_control.so" name="gazebo_ros_control"/>
  </gazebo>
</robot>

